2025-07-28 09:53:49,843 - __main__ - INFO - Starting FoodBot...
2025-07-28 09:53:52,272 - __main__ - INFO - Database connection successful
2025-07-28 09:53:53,314 - __main__ - INFO - Webhook removed
2025-07-28 10:56:04,985 - __main__ - CRITICAL - Bot crashed: HTTPSConnectionPool(host='api.telegram.org', port=443): Max retries exceeded with url: /bot7935652028:AAFne5ZN0ypdZtgNNX_9kkAgTe9Livs-rUo/getUpdates?offset=1&timeout=20 (Caused by NewConnectionError('<urllib3.connection.HTTPSConnection object at 0x70526f5c2bc0>: Failed to establish a new connection: [Errno 101] Network is unreachable'))
2025-07-29 23:14:34,343 - __main__ - INFO - Starting FoodBot...
2025-07-29 23:14:40,025 - __main__ - INFO - Database connection successful
2025-07-29 23:14:42,292 - __main__ - INFO - Webhook removed
2025-07-29 23:14:56,678 - __main__ - INFO - Saved user 916638938 to database
2025-07-29 23:14:56,678 - __main__ - INFO - User 916638938 initialized
2025-07-29 23:37:49,601 - __main__ - CRITICAL - Bot crashed: HTTPSConnectionPool(host='api.telegram.org', port=443): Read timed out. (read timeout=25)
2025-07-30 09:41:38,130 - __main__ - INFO - Starting FoodBot...
2025-07-30 09:41:38,133 - __main__ - ERROR - Database connection failed: 'NoneType' object has no attribute 'encode'
2025-07-30 09:41:38,134 - __main__ - CRITICAL - Bot crashed: 'NoneType' object has no attribute 'encode'
2025-07-30 09:42:33,648 - __main__ - INFO - Starting FoodBot...
2025-07-30 09:42:33,648 - __main__ - ERROR - Database connection failed: 'NoneType' object has no attribute 'encode'
2025-07-30 09:42:33,648 - __main__ - CRITICAL - Bot crashed: 'NoneType' object has no attribute 'encode'
2025-07-30 09:46:15,114 - __main__ - INFO - Starting FoodBot...
2025-07-30 09:46:15,114 - __main__ - ERROR - Database connection failed: 'NoneType' object has no attribute 'encode'
2025-07-30 09:46:15,114 - __main__ - CRITICAL - Bot crashed: 'NoneType' object has no attribute 'encode'
2025-07-30 10:03:47,931 - __main__ - INFO - Starting FoodBot...
2025-07-30 10:03:47,932 - __main__ - ERROR - Database connection failed: 'NoneType' object has no attribute 'encode'
2025-07-30 10:03:47,933 - __main__ - CRITICAL - Bot crashed: 'NoneType' object has no attribute 'encode'
2025-07-30 10:07:37,460 - __main__ - INFO - Starting FoodBot...
2025-07-30 10:07:45,138 - __main__ - INFO - Database connection successful
2025-07-30 10:08:00,751 - __main__ - CRITICAL - Bot crashed: HTTPSConnectionPool(host='api.telegram.org', port=443): Max retries exceeded with url: /bot7935652028:AAFne5ZN0ypdZtgNNX_9kkAgTe9Livs-rUo/setWebhook?url= (Caused by NewConnectionError('<urllib3.connection.HTTPSConnection object at 0x7c32a5d6d990>: Failed to establish a new connection: [Errno 101] Network is unreachable'))
2025-07-30 10:08:18,924 - __main__ - INFO - Starting FoodBot...
2025-07-30 10:08:26,274 - __main__ - INFO - Database connection successful
2025-07-30 10:08:41,328 - __main__ - CRITICAL - Bot crashed: HTTPSConnectionPool(host='api.telegram.org', port=443): Max retries exceeded with url: /bot7935652028:AAFne5ZN0ypdZtgNNX_9kkAgTe9Livs-rUo/setWebhook?url= (Caused by NewConnectionError('<urllib3.connection.HTTPSConnection object at 0x7ca404e8d990>: Failed to establish a new connection: [Errno 101] Network is unreachable'))
2025-07-30 10:13:39,015 - __main__ - INFO - Starting FoodBot...
2025-07-30 10:13:40,852 - __main__ - INFO - Database connection successful
2025-07-30 10:13:42,185 - __main__ - INFO - Webhook removed
2025-07-30 10:14:12,033 - __main__ - INFO - Saved user 916638938 to database
2025-07-30 10:14:12,035 - __main__ - INFO - User 916638938 initialized
2025-07-30 10:14:27,065 - __main__ - ERROR - Start failed for 916638938: HTTPSConnectionPool(host='api.telegram.org', port=443): Max retries exceeded with url: /bot7935652028:AAFne5ZN0ypdZtgNNX_9kkAgTe9Livs-rUo/sendMessage?chat_id=916638938&text=Welcome+natnael%21+Click+below+to+start+ordering.&reply_markup=%7B%22inline_keyboard%22%3A+%5B%5B%7B%22text%22%3A+%22%5Cud83c%5Cudf54+Order+Food%22%2C+%22web_app%22%3A+%7B%22url%22%3A+%22https%3A%2F%2Ffood-bot-vulm.onrender.com%22%7D%7D%5D%5D%7D (Caused by NewConnectionError('<urllib3.connection.HTTPSConnection object at 0x7e1ac4a67940>: Failed to establish a new connection: [Errno 101] Network is unreachable'))
2025-07-30 10:14:42,965 - __main__ - INFO - Starting FoodBot...
2025-07-30 10:14:45,195 - __main__ - INFO - Database connection successful
2025-07-30 10:14:45,751 - __main__ - INFO - Webhook removed
2025-07-30 10:14:54,259 - __main__ - INFO - Saved user 916638938 to database
2025-07-30 10:14:54,261 - __main__ - INFO - User 916638938 initialized
2025-07-30 10:46:46,931 - TeleBot - ERROR - Threaded polling exception: A request to the Telegram API was unsuccessful. Error code: 409. Description: Conflict: terminated by setWebhook request
2025-07-30 10:46:46,934 - TeleBot - ERROR - Exception traceback:
Traceback (most recent call last):
  File "/home/natty/.local/lib/python3.10/site-packages/telebot/__init__.py", line 1214, in __threaded_polling
    polling_thread.raise_exceptions()
  File "/home/natty/.local/lib/python3.10/site-packages/telebot/util.py", line 111, in raise_exceptions
    raise self.exception_info
  File "/home/natty/.local/lib/python3.10/site-packages/telebot/util.py", line 93, in run
    task(*args, **kwargs)
  File "/home/natty/.local/lib/python3.10/site-packages/telebot/__init__.py", line 676, in __retrieve_updates
    updates = self.get_updates(offset=(self.last_update_id + 1),
  File "/home/natty/.local/lib/python3.10/site-packages/telebot/__init__.py", line 648, in get_updates
    json_updates = apihelper.get_updates(
  File "/home/natty/.local/lib/python3.10/site-packages/telebot/apihelper.py", line 330, in get_updates
    return _make_request(token, method_url, params=payload)
  File "/home/natty/.local/lib/python3.10/site-packages/telebot/apihelper.py", line 168, in _make_request
    json_result = _check_result(method_name, result)
  File "/home/natty/.local/lib/python3.10/site-packages/telebot/apihelper.py", line 195, in _check_result
    raise ApiTelegramException(method_name, result, result_json)
telebot.apihelper.ApiTelegramException: A request to the Telegram API was unsuccessful. Error code: 409. Description: Conflict: terminated by setWebhook request

2025-07-30 10:46:51,592 - TeleBot - ERROR - Threaded polling exception: A request to the Telegram API was unsuccessful. Error code: 409. Description: Conflict: can't use getUpdates method while webhook is active; use deleteWebhook to delete the webhook first
2025-07-30 10:46:51,595 - TeleBot - ERROR - Exception traceback:
Traceback (most recent call last):
  File "/home/natty/.local/lib/python3.10/site-packages/telebot/__init__.py", line 1214, in __threaded_polling
    polling_thread.raise_exceptions()
  File "/home/natty/.local/lib/python3.10/site-packages/telebot/util.py", line 111, in raise_exceptions
    raise self.exception_info
  File "/home/natty/.local/lib/python3.10/site-packages/telebot/util.py", line 93, in run
    task(*args, **kwargs)
  File "/home/natty/.local/lib/python3.10/site-packages/telebot/__init__.py", line 676, in __retrieve_updates
    updates = self.get_updates(offset=(self.last_update_id + 1),
  File "/home/natty/.local/lib/python3.10/site-packages/telebot/__init__.py", line 648, in get_updates
    json_updates = apihelper.get_updates(
  File "/home/natty/.local/lib/python3.10/site-packages/telebot/apihelper.py", line 330, in get_updates
    return _make_request(token, method_url, params=payload)
  File "/home/natty/.local/lib/python3.10/site-packages/telebot/apihelper.py", line 168, in _make_request
    json_result = _check_result(method_name, result)
  File "/home/natty/.local/lib/python3.10/site-packages/telebot/apihelper.py", line 195, in _check_result
    raise ApiTelegramException(method_name, result, result_json)
telebot.apihelper.ApiTelegramException: A request to the Telegram API was unsuccessful. Error code: 409. Description: Conflict: can't use getUpdates method while webhook is active; use deleteWebhook to delete the webhook first

2025-07-30 10:46:53,446 - TeleBot - ERROR - Threaded polling exception: A request to the Telegram API was unsuccessful. Error code: 409. Description: Conflict: can't use getUpdates method while webhook is active; use deleteWebhook to delete the webhook first
2025-07-30 10:46:53,447 - TeleBot - ERROR - Exception traceback:
Traceback (most recent call last):
  File "/home/natty/.local/lib/python3.10/site-packages/telebot/__init__.py", line 1214, in __threaded_polling
    polling_thread.raise_exceptions()
  File "/home/natty/.local/lib/python3.10/site-packages/telebot/util.py", line 111, in raise_exceptions
    raise self.exception_info
  File "/home/natty/.local/lib/python3.10/site-packages/telebot/util.py", line 93, in run
    task(*args, **kwargs)
  File "/home/natty/.local/lib/python3.10/site-packages/telebot/__init__.py", line 676, in __retrieve_updates
    updates = self.get_updates(offset=(self.last_update_id + 1),
  File "/home/natty/.local/lib/python3.10/site-packages/telebot/__init__.py", line 648, in get_updates
    json_updates = apihelper.get_updates(
  File "/home/natty/.local/lib/python3.10/site-packages/telebot/apihelper.py", line 330, in get_updates
    return _make_request(token, method_url, params=payload)
  File "/home/natty/.local/lib/python3.10/site-packages/telebot/apihelper.py", line 168, in _make_request
    json_result = _check_result(method_name, result)
  File "/home/natty/.local/lib/python3.10/site-packages/telebot/apihelper.py", line 195, in _check_result
    raise ApiTelegramException(method_name, result, result_json)
telebot.apihelper.ApiTelegramException: A request to the Telegram API was unsuccessful. Error code: 409. Description: Conflict: can't use getUpdates method while webhook is active; use deleteWebhook to delete the webhook first

2025-07-30 10:46:58,715 - TeleBot - ERROR - Threaded polling exception: A request to the Telegram API was unsuccessful. Error code: 409. Description: Conflict: can't use getUpdates method while webhook is active; use deleteWebhook to delete the webhook first
2025-07-30 10:46:58,717 - TeleBot - ERROR - Exception traceback:
Traceback (most recent call last):
  File "/home/natty/.local/lib/python3.10/site-packages/telebot/__init__.py", line 1214, in __threaded_polling
    polling_thread.raise_exceptions()
  File "/home/natty/.local/lib/python3.10/site-packages/telebot/util.py", line 111, in raise_exceptions
    raise self.exception_info
  File "/home/natty/.local/lib/python3.10/site-packages/telebot/util.py", line 93, in run
    task(*args, **kwargs)
  File "/home/natty/.local/lib/python3.10/site-packages/telebot/__init__.py", line 676, in __retrieve_updates
    updates = self.get_updates(offset=(self.last_update_id + 1),
  File "/home/natty/.local/lib/python3.10/site-packages/telebot/__init__.py", line 648, in get_updates
    json_updates = apihelper.get_updates(
  File "/home/natty/.local/lib/python3.10/site-packages/telebot/apihelper.py", line 330, in get_updates
    return _make_request(token, method_url, params=payload)
  File "/home/natty/.local/lib/python3.10/site-packages/telebot/apihelper.py", line 168, in _make_request
    json_result = _check_result(method_name, result)
  File "/home/natty/.local/lib/python3.10/site-packages/telebot/apihelper.py", line 195, in _check_result
    raise ApiTelegramException(method_name, result, result_json)
telebot.apihelper.ApiTelegramException: A request to the Telegram API was unsuccessful. Error code: 409. Description: Conflict: can't use getUpdates method while webhook is active; use deleteWebhook to delete the webhook first

2025-07-30 10:47:01,977 - TeleBot - ERROR - Threaded polling exception: A request to the Telegram API was unsuccessful. Error code: 409. Description: Conflict: can't use getUpdates method while webhook is active; use deleteWebhook to delete the webhook first
2025-07-30 10:47:01,979 - TeleBot - ERROR - Exception traceback:
Traceback (most recent call last):
  File "/home/natty/.local/lib/python3.10/site-packages/telebot/__init__.py", line 1214, in __threaded_polling
    polling_thread.raise_exceptions()
  File "/home/natty/.local/lib/python3.10/site-packages/telebot/util.py", line 111, in raise_exceptions
    raise self.exception_info
  File "/home/natty/.local/lib/python3.10/site-packages/telebot/util.py", line 93, in run
    task(*args, **kwargs)
  File "/home/natty/.local/lib/python3.10/site-packages/telebot/__init__.py", line 676, in __retrieve_updates
    updates = self.get_updates(offset=(self.last_update_id + 1),
  File "/home/natty/.local/lib/python3.10/site-packages/telebot/__init__.py", line 648, in get_updates
    json_updates = apihelper.get_updates(
  File "/home/natty/.local/lib/python3.10/site-packages/telebot/apihelper.py", line 330, in get_updates
    return _make_request(token, method_url, params=payload)
  File "/home/natty/.local/lib/python3.10/site-packages/telebot/apihelper.py", line 168, in _make_request
    json_result = _check_result(method_name, result)
  File "/home/natty/.local/lib/python3.10/site-packages/telebot/apihelper.py", line 195, in _check_result
    raise ApiTelegramException(method_name, result, result_json)
telebot.apihelper.ApiTelegramException: A request to the Telegram API was unsuccessful. Error code: 409. Description: Conflict: can't use getUpdates method while webhook is active; use deleteWebhook to delete the webhook first

2025-07-30 10:47:07,220 - TeleBot - ERROR - Threaded polling exception: A request to the Telegram API was unsuccessful. Error code: 409. Description: Conflict: can't use getUpdates method while webhook is active; use deleteWebhook to delete the webhook first
2025-07-30 10:47:07,221 - TeleBot - ERROR - Exception traceback:
Traceback (most recent call last):
  File "/home/natty/.local/lib/python3.10/site-packages/telebot/__init__.py", line 1214, in __threaded_polling
    polling_thread.raise_exceptions()
  File "/home/natty/.local/lib/python3.10/site-packages/telebot/util.py", line 111, in raise_exceptions
    raise self.exception_info
  File "/home/natty/.local/lib/python3.10/site-packages/telebot/util.py", line 93, in run
    task(*args, **kwargs)
  File "/home/natty/.local/lib/python3.10/site-packages/telebot/__init__.py", line 676, in __retrieve_updates
    updates = self.get_updates(offset=(self.last_update_id + 1),
  File "/home/natty/.local/lib/python3.10/site-packages/telebot/__init__.py", line 648, in get_updates
    json_updates = apihelper.get_updates(
  File "/home/natty/.local/lib/python3.10/site-packages/telebot/apihelper.py", line 330, in get_updates
    return _make_request(token, method_url, params=payload)
  File "/home/natty/.local/lib/python3.10/site-packages/telebot/apihelper.py", line 168, in _make_request
    json_result = _check_result(method_name, result)
  File "/home/natty/.local/lib/python3.10/site-packages/telebot/apihelper.py", line 195, in _check_result
    raise ApiTelegramException(method_name, result, result_json)
telebot.apihelper.ApiTelegramException: A request to the Telegram API was unsuccessful. Error code: 409. Description: Conflict: can't use getUpdates method while webhook is active; use deleteWebhook to delete the webhook first

2025-07-30 10:47:16,651 - TeleBot - ERROR - Threaded polling exception: A request to the Telegram API was unsuccessful. Error code: 409. Description: Conflict: can't use getUpdates method while webhook is active; use deleteWebhook to delete the webhook first
2025-07-30 10:47:16,653 - TeleBot - ERROR - Exception traceback:
Traceback (most recent call last):
  File "/home/natty/.local/lib/python3.10/site-packages/telebot/__init__.py", line 1214, in __threaded_polling
    polling_thread.raise_exceptions()
  File "/home/natty/.local/lib/python3.10/site-packages/telebot/util.py", line 111, in raise_exceptions
    raise self.exception_info
  File "/home/natty/.local/lib/python3.10/site-packages/telebot/util.py", line 93, in run
    task(*args, **kwargs)
  File "/home/natty/.local/lib/python3.10/site-packages/telebot/__init__.py", line 676, in __retrieve_updates
    updates = self.get_updates(offset=(self.last_update_id + 1),
  File "/home/natty/.local/lib/python3.10/site-packages/telebot/__init__.py", line 648, in get_updates
    json_updates = apihelper.get_updates(
  File "/home/natty/.local/lib/python3.10/site-packages/telebot/apihelper.py", line 330, in get_updates
    return _make_request(token, method_url, params=payload)
  File "/home/natty/.local/lib/python3.10/site-packages/telebot/apihelper.py", line 168, in _make_request
    json_result = _check_result(method_name, result)
  File "/home/natty/.local/lib/python3.10/site-packages/telebot/apihelper.py", line 195, in _check_result
    raise ApiTelegramException(method_name, result, result_json)
telebot.apihelper.ApiTelegramException: A request to the Telegram API was unsuccessful. Error code: 409. Description: Conflict: can't use getUpdates method while webhook is active; use deleteWebhook to delete the webhook first

2025-07-30 10:47:33,955 - TeleBot - ERROR - Threaded polling exception: A request to the Telegram API was unsuccessful. Error code: 409. Description: Conflict: can't use getUpdates method while webhook is active; use deleteWebhook to delete the webhook first
2025-07-30 10:47:33,958 - TeleBot - ERROR - Exception traceback:
Traceback (most recent call last):
  File "/home/natty/.local/lib/python3.10/site-packages/telebot/__init__.py", line 1214, in __threaded_polling
    polling_thread.raise_exceptions()
  File "/home/natty/.local/lib/python3.10/site-packages/telebot/util.py", line 111, in raise_exceptions
    raise self.exception_info
  File "/home/natty/.local/lib/python3.10/site-packages/telebot/util.py", line 93, in run
    task(*args, **kwargs)
  File "/home/natty/.local/lib/python3.10/site-packages/telebot/__init__.py", line 676, in __retrieve_updates
    updates = self.get_updates(offset=(self.last_update_id + 1),
  File "/home/natty/.local/lib/python3.10/site-packages/telebot/__init__.py", line 648, in get_updates
    json_updates = apihelper.get_updates(
  File "/home/natty/.local/lib/python3.10/site-packages/telebot/apihelper.py", line 330, in get_updates
    return _make_request(token, method_url, params=payload)
  File "/home/natty/.local/lib/python3.10/site-packages/telebot/apihelper.py", line 168, in _make_request
    json_result = _check_result(method_name, result)
  File "/home/natty/.local/lib/python3.10/site-packages/telebot/apihelper.py", line 195, in _check_result
    raise ApiTelegramException(method_name, result, result_json)
telebot.apihelper.ApiTelegramException: A request to the Telegram API was unsuccessful. Error code: 409. Description: Conflict: can't use getUpdates method while webhook is active; use deleteWebhook to delete the webhook first

2025-07-30 10:48:07,248 - TeleBot - ERROR - Threaded polling exception: A request to the Telegram API was unsuccessful. Error code: 409. Description: Conflict: can't use getUpdates method while webhook is active; use deleteWebhook to delete the webhook first
2025-07-30 10:48:07,249 - TeleBot - ERROR - Exception traceback:
Traceback (most recent call last):
  File "/home/natty/.local/lib/python3.10/site-packages/telebot/__init__.py", line 1214, in __threaded_polling
    polling_thread.raise_exceptions()
  File "/home/natty/.local/lib/python3.10/site-packages/telebot/util.py", line 111, in raise_exceptions
    raise self.exception_info
  File "/home/natty/.local/lib/python3.10/site-packages/telebot/util.py", line 93, in run
    task(*args, **kwargs)
  File "/home/natty/.local/lib/python3.10/site-packages/telebot/__init__.py", line 676, in __retrieve_updates
    updates = self.get_updates(offset=(self.last_update_id + 1),
  File "/home/natty/.local/lib/python3.10/site-packages/telebot/__init__.py", line 648, in get_updates
    json_updates = apihelper.get_updates(
  File "/home/natty/.local/lib/python3.10/site-packages/telebot/apihelper.py", line 330, in get_updates
    return _make_request(token, method_url, params=payload)
  File "/home/natty/.local/lib/python3.10/site-packages/telebot/apihelper.py", line 168, in _make_request
    json_result = _check_result(method_name, result)
  File "/home/natty/.local/lib/python3.10/site-packages/telebot/apihelper.py", line 195, in _check_result
    raise ApiTelegramException(method_name, result, result_json)
telebot.apihelper.ApiTelegramException: A request to the Telegram API was unsuccessful. Error code: 409. Description: Conflict: can't use getUpdates method while webhook is active; use deleteWebhook to delete the webhook first

2025-07-30 10:48:14,349 - __main__ - INFO - Starting FoodBot...
2025-07-30 10:48:17,177 - __main__ - INFO - Database connection successful
2025-07-30 10:48:18,423 - __main__ - INFO - Webhook removed
2025-07-30 10:49:28,645 - __main__ - INFO - Saved user 916638938 to database
2025-07-30 10:49:28,651 - __main__ - INFO - User 916638938 initialized
2025-07-30 10:58:23,243 - __main__ - CRITICAL - Bot crashed: HTTPSConnectionPool(host='api.telegram.org', port=443): Read timed out. (read timeout=25)
2025-07-30 11:21:08,432 - __main__ - INFO - Starting FoodBot...
2025-07-30 11:21:10,491 - __main__ - INFO - Database connection successful
2025-07-30 11:21:11,303 - __main__ - INFO - Webhook removed
2025-07-30 11:31:34,906 - __main__ - CRITICAL - Bot crashed: HTTPSConnectionPool(host='api.telegram.org', port=443): Max retries exceeded with url: /bot7935652028:AAFne5ZN0ypdZtgNNX_9kkAgTe9Livs-rUo/getUpdates?offset=1&timeout=20 (Caused by NewConnectionError('<urllib3.connection.HTTPSConnection object at 0x7336ed49e710>: Failed to establish a new connection: [Errno 101] Network is unreachable'))
2025-07-30 14:54:20,833 - __main__ - INFO - Starting FoodBot...
2025-07-30 14:54:23,580 - __main__ - INFO - Database connection successful
2025-07-30 14:54:24,606 - __main__ - INFO - Webhook removed
2025-07-30 16:05:22,299 - __main__ - INFO - Saved user 916638938 to database
2025-07-30 16:05:22,455 - __main__ - INFO - User 916638938 initialized
2025-07-30 18:25:21,444 - __main__ - CRITICAL - Bot crashed: HTTPSConnectionPool(host='api.telegram.org', port=443): Read timed out. (read timeout=25)
2025-07-30 22:09:44,502 - __main__ - INFO - Starting FoodBot...
2025-07-30 22:09:57,623 - __main__ - INFO - Database connection successful
2025-07-30 22:10:01,898 - __main__ - INFO - Webhook removed
2025-07-30 22:10:23,744 - __main__ - CRITICAL - Bot crashed: HTTPSConnectionPool(host='api.telegram.org', port=443): Max retries exceeded with url: /bot7935652028:AAFne5ZN0ypdZtgNNX_9kkAgTe9Livs-rUo/getUpdates?offset=1&timeout=20 (Caused by NewConnectionError('<urllib3.connection.HTTPSConnection object at 0x75008b8069e0>: Failed to establish a new connection: [Errno 101] Network is unreachable'))
2025-07-30 22:59:09,541 - __main__ - INFO - Starting FoodBot...
2025-07-30 22:59:29,341 - __main__ - INFO - Database connection successful
2025-07-30 22:59:30,623 - __main__ - INFO - Webhook removed
2025-07-31 00:01:28,487 - __main__ - CRITICAL - Bot crashed: HTTPSConnectionPool(host='api.telegram.org', port=443): Max retries exceeded with url: /bot7935652028:AAFne5ZN0ypdZtgNNX_9kkAgTe9Livs-rUo/getUpdates?offset=1&timeout=20 (Caused by NewConnectionError('<urllib3.connection.HTTPSConnection object at 0x740a399d66e0>: Failed to establish a new connection: [Errno 101] Network is unreachable'))
2025-07-31 00:29:01,781 - __main__ - INFO - Starting FoodBot...
2025-07-31 00:29:03,981 - __main__ - INFO - Database connection successful
2025-07-31 00:29:19,120 - __main__ - CRITICAL - Bot crashed: HTTPSConnectionPool(host='api.telegram.org', port=443): Max retries exceeded with url: /bot7935652028:AAFne5ZN0ypdZtgNNX_9kkAgTe9Livs-rUo/setWebhook?url= (Caused by NewConnectionError('<urllib3.connection.HTTPSConnection object at 0x705b70361990>: Failed to establish a new connection: [Errno 101] Network is unreachable'))
2025-07-31 00:29:22,496 - __main__ - INFO - Starting FoodBot...
2025-07-31 00:29:25,070 - __main__ - INFO - Database connection successful
2025-07-31 00:29:40,232 - __main__ - CRITICAL - Bot crashed: HTTPSConnectionPool(host='api.telegram.org', port=443): Max retries exceeded with url: /bot7935652028:AAFne5ZN0ypdZtgNNX_9kkAgTe9Livs-rUo/setWebhook?url= (Caused by NewConnectionError('<urllib3.connection.HTTPSConnection object at 0x795d3e561990>: Failed to establish a new connection: [Errno 101] Network is unreachable'))
2025-07-31 00:29:45,914 - __main__ - INFO - Starting FoodBot...
2025-07-31 00:29:47,549 - __main__ - INFO - Database connection successful
2025-07-31 00:30:02,568 - __main__ - CRITICAL - Bot crashed: HTTPSConnectionPool(host='api.telegram.org', port=443): Max retries exceeded with url: /bot7935652028:AAFne5ZN0ypdZtgNNX_9kkAgTe9Livs-rUo/setWebhook?url= (Caused by NewConnectionError('<urllib3.connection.HTTPSConnection object at 0x738c90865990>: Failed to establish a new connection: [Errno 101] Network is unreachable'))
2025-07-31 00:30:06,863 - __main__ - INFO - Starting FoodBot...
2025-07-31 00:30:08,635 - __main__ - INFO - Database connection successful
2025-07-31 00:30:23,654 - __main__ - CRITICAL - Bot crashed: HTTPSConnectionPool(host='api.telegram.org', port=443): Max retries exceeded with url: /bot7935652028:AAFne5ZN0ypdZtgNNX_9kkAgTe9Livs-rUo/setWebhook?url= (Caused by NewConnectionError('<urllib3.connection.HTTPSConnection object at 0x7fa731485990>: Failed to establish a new connection: [Errno 101] Network is unreachable'))
2025-07-31 00:30:27,154 - __main__ - INFO - Starting FoodBot...
2025-07-31 00:30:29,012 - __main__ - INFO - Database connection successful
2025-07-31 00:30:29,737 - __main__ - INFO - Webhook removed
2025-07-31 00:41:08,521 - __main__ - CRITICAL - Bot crashed: HTTPSConnectionPool(host='api.telegram.org', port=443): Max retries exceeded with url: /bot7935652028:AAFne5ZN0ypdZtgNNX_9kkAgTe9Livs-rUo/getUpdates?offset=1&timeout=20 (Caused by NewConnectionError('<urllib3.connection.HTTPSConnection object at 0x732816b9e710>: Failed to establish a new connection: [Errno 101] Network is unreachable'))
2025-07-31 00:54:10,376 - __main__ - INFO - Starting FoodBot...
2025-07-31 00:54:12,897 - __main__ - INFO - Database connection successful
2025-07-31 00:54:13,955 - __main__ - INFO - Webhook removed
2025-07-31 01:01:44,504 - __main__ - CRITICAL - Bot crashed: HTTPSConnectionPool(host='api.telegram.org', port=443): Read timed out. (read timeout=25)
2025-07-31 01:08:40,757 - __main__ - INFO - Starting FoodBot...
2025-07-31 01:08:42,890 - __main__ - INFO - Database connection successful
2025-07-31 01:08:43,812 - __main__ - INFO - Webhook removed
2025-07-31 19:54:28,650 - __main__ - INFO - Starting FoodBot...
2025-07-31 19:54:34,709 - __main__ - INFO - Database connection successful
2025-07-31 19:54:42,252 - __main__ - INFO - Webhook removed
2025-07-31 21:08:27,463 - __main__ - CRITICAL - Bot crashed: HTTPSConnectionPool(host='api.telegram.org', port=443): Read timed out. (read timeout=25)
2025-07-31 23:25:33,652 - __main__ - INFO - Starting FoodBot...
2025-07-31 23:25:35,390 - __main__ - INFO - Database connection successful
2025-07-31 23:25:36,313 - __main__ - INFO - Webhook removed
2025-08-01 02:14:33,906 - __main__ - CRITICAL - Bot crashed: HTTPSConnectionPool(host='api.telegram.org', port=443): Read timed out. (read timeout=25)
2025-08-01 17:16:11,286 - __main__ - INFO - Starting FoodBot...
2025-08-01 17:16:13,387 - __main__ - INFO - Database connection successful
2025-08-01 17:16:14,218 - __main__ - INFO - Webhook removed
2025-08-01 19:33:13,593 - __main__ - CRITICAL - Bot crashed: HTTPSConnectionPool(host='api.telegram.org', port=443): Read timed out. (read timeout=25)
2025-08-01 22:18:19,265 - __main__ - INFO - Starting FoodBot...
2025-08-01 22:18:21,805 - __main__ - INFO - Database connection successful
2025-08-01 22:18:28,357 - __main__ - INFO - Webhook removed
2025-08-02 13:03:11,463 - __main__ - INFO - Starting FoodBot...
2025-08-02 13:03:14,495 - __main__ - INFO - Database connection successful
2025-08-02 13:03:16,060 - __main__ - INFO - Webhook removed
2025-08-02 13:08:39,740 - __main__ - CRITICAL - Bot crashed: HTTPSConnectionPool(host='api.telegram.org', port=443): Read timed out. (read timeout=25)
2025-08-02 17:51:30,283 - __main__ - INFO - Starting FoodBot...
2025-08-02 17:51:32,331 - __main__ - INFO - Database connection successful
2025-08-02 17:51:33,370 - __main__ - INFO - Webhook removed
2025-08-02 19:04:52,152 - __main__ - INFO - Starting FoodBot...
2025-08-02 19:04:55,120 - __main__ - INFO - Database connection successful
2025-08-02 19:04:56,145 - __main__ - INFO - Webhook removed
2025-08-02 19:37:18,281 - __main__ - CRITICAL - Bot crashed: HTTPSConnectionPool(host='api.telegram.org', port=443): Read timed out. (read timeout=25)
2025-08-02 20:58:31,242 - __main__ - INFO - Starting FoodBot...
2025-08-02 20:58:33,503 - __main__ - INFO - Database connection successful
2025-08-02 20:58:39,211 - __main__ - INFO - Webhook removed
2025-08-02 22:03:13,484 - __main__ - CRITICAL - Bot crashed: HTTPSConnectionPool(host='api.telegram.org', port=443): Read timed out. (read timeout=25)
2025-08-03 15:05:21,324 - __main__ - INFO - Starting FoodBot...
2025-08-03 15:05:23,469 - __main__ - INFO - Database connection successful
2025-08-03 15:05:24,408 - __main__ - INFO - Webhook removed
2025-08-03 16:28:15,629 - __main__ - CRITICAL - Bot crashed: HTTPSConnectionPool(host='api.telegram.org', port=443): Read timed out. (read timeout=25)
2025-08-04 14:19:41,295 - __main__ - INFO - Starting FoodBot...
2025-08-04 14:20:02,775 - __main__ - INFO - Database connection successful
2025-08-04 14:20:04,182 - __main__ - INFO - Webhook removed
2025-08-05 06:13:36,732 - __main__ - CRITICAL - Bot crashed: HTTPSConnectionPool(host='api.telegram.org', port=443): Read timed out. (read timeout=25)
2025-08-05 11:55:17,667 - __main__ - INFO - Starting FoodBot...
2025-08-05 11:55:20,370 - __main__ - INFO - Database connection successful
2025-08-05 11:55:21,561 - __main__ - INFO - Webhook removed
2025-08-05 14:57:16,504 - __main__ - CRITICAL - Bot crashed: HTTPSConnectionPool(host='api.telegram.org', port=443): Read timed out. (read timeout=25)
2025-08-05 16:01:35,580 - __main__ - INFO - Starting FoodBot...
2025-08-05 16:01:37,574 - __main__ - INFO - Database connection successful
2025-08-05 16:01:38,598 - __main__ - INFO - Webhook removed
2025-08-05 16:18:44,238 - __main__ - CRITICAL - Bot crashed: HTTPSConnectionPool(host='api.telegram.org', port=443): Read timed out. (read timeout=25)
2025-08-05 16:33:50,040 - __main__ - INFO - Starting FoodBot...
2025-08-05 16:33:52,260 - __main__ - INFO - Database connection successful
2025-08-05 16:33:53,013 - __main__ - INFO - Webhook removed
2025-08-05 22:20:19,270 - __main__ - CRITICAL - Bot crashed: HTTPSConnectionPool(host='api.telegram.org', port=443): Read timed out. (read timeout=25)
2025-08-05 22:29:24,348 - __main__ - INFO - Starting FoodBot...
2025-08-05 22:29:30,540 - __main__ - INFO - Database connection successful
2025-08-05 22:29:35,042 - __main__ - INFO - Webhook removed
2025-08-05 23:00:38,675 - __main__ - CRITICAL - Bot crashed: HTTPSConnectionPool(host='api.telegram.org', port=443): Read timed out. (read timeout=25)
2025-08-05 23:06:10,264 - __main__ - INFO - Starting FoodBot...
2025-08-05 23:06:12,883 - __main__ - INFO - Database connection successful
2025-08-05 23:06:13,937 - __main__ - INFO - Webhook removed
2025-08-05 23:14:14,928 - __main__ - CRITICAL - Bot crashed: HTTPSConnectionPool(host='api.telegram.org', port=443): Read timed out. (read timeout=25)
2025-08-06 00:05:27,292 - __main__ - INFO - Starting FoodBot...
2025-08-06 00:05:29,057 - __main__ - INFO - Database connection successful
2025-08-06 00:05:29,645 - __main__ - INFO - Webhook removed
2025-08-08 14:50:11,303 - __main__ - INFO - Starting FoodBot...
2025-08-08 14:50:13,321 - __main__ - INFO - Database connection successful
2025-08-08 14:50:14,083 - __main__ - INFO - Webhook removed
2025-08-08 15:40:43,892 - __main__ - CRITICAL - Bot crashed: HTTPSConnectionPool(host='api.telegram.org', port=443): Read timed out. (read timeout=25)
2025-08-08 21:52:09,193 - __main__ - INFO - Starting FoodBot...
2025-08-08 21:52:11,441 - __main__ - INFO - Database connection successful
2025-08-08 21:52:12,184 - __main__ - INFO - Webhook removed
2025-08-08 21:52:38,255 - __main__ - ERROR - Failed to save user 916638938: column "session_token" of relation "users" does not exist
LINE 2:     INSERT INTO users (chat_id, name, session_token)
                                              ^
2025-08-08 21:52:38,256 - __main__ - ERROR - Start failed for 916638938: column "session_token" of relation "users" does not exist
LINE 2:     INSERT INTO users (chat_id, name, session_token)
                                              ^
2025-08-08 21:53:28,255 - __main__ - INFO - Starting FoodBot...
2025-08-08 21:53:30,011 - __main__ - INFO - Database connection successful
2025-08-08 21:53:30,576 - __main__ - INFO - Webhook removed
2025-08-08 21:53:36,419 - __main__ - ERROR - Failed to save user 916638938: INSERT has more expressions than target columns
LINE 3:     VALUES ($1, $2, $3)
                            ^
2025-08-08 21:53:36,419 - __main__ - ERROR - Start failed for 916638938: INSERT has more expressions than target columns
LINE 3:     VALUES ($1, $2, $3)
                            ^
2025-08-08 21:53:56,107 - __main__ - ERROR - Failed to save user 916638938: INSERT has more expressions than target columns
LINE 3:     VALUES ($1, $2, $3)
                            ^
2025-08-08 21:53:56,108 - __main__ - ERROR - Start failed for 916638938: INSERT has more expressions than target columns
LINE 3:     VALUES ($1, $2, $3)
                            ^
2025-08-08 21:54:03,494 - __main__ - INFO - Starting FoodBot...
2025-08-08 21:54:05,534 - __main__ - INFO - Database connection successful
2025-08-08 21:54:06,110 - __main__ - INFO - Webhook removed
2025-08-08 21:54:10,923 - __main__ - ERROR - Failed to save user 916638938: the query has 2 placeholders but 3 parameters were passed
2025-08-08 21:54:10,924 - __main__ - ERROR - Start failed for 916638938: the query has 2 placeholders but 3 parameters were passed
2025-08-08 21:54:34,438 - __main__ - INFO - Starting FoodBot...
2025-08-08 21:54:36,266 - __main__ - INFO - Database connection successful
2025-08-08 21:54:36,903 - __main__ - INFO - Webhook removed
2025-08-08 21:54:38,561 - __main__ - ERROR - Start failed for 916638938: save_user_to_db() got an unexpected keyword argument 'session_token'
2025-08-08 21:55:44,998 - __main__ - INFO - Starting FoodBot...
2025-08-08 21:55:46,866 - __main__ - INFO - Database connection successful
2025-08-08 21:55:47,583 - __main__ - INFO - Webhook removed
2025-08-08 21:55:53,822 - __main__ - INFO - Saved user 916638938 to database
2025-08-08 21:55:53,823 - __main__ - INFO - User 916638938 initialized
2025-08-08 22:15:15,733 - __main__ - INFO - Saved user 6523397595 to database
2025-08-08 22:15:15,735 - __main__ - INFO - User 6523397595 initialized
